2021-10-23 16:12:38,390 - my_application - ERROR - 296957065
Traceback (most recent call last):
  File "/home/virtman/Durak_bot/card-bot.py", line 265, in <module>
    bot.polling(none_stop=True, interval=2 )
  File "/home/virtman/Durak_bot/venv/lib/python3.8/site-packages/telebot/__init__.py", line 619, in polling
    self.__threaded_polling(none_stop, interval, timeout, long_polling_timeout, allowed_updates)
  File "/home/virtman/Durak_bot/venv/lib/python3.8/site-packages/telebot/__init__.py", line 678, in __threaded_polling
    raise e
  File "/home/virtman/Durak_bot/venv/lib/python3.8/site-packages/telebot/__init__.py", line 641, in __threaded_polling
    self.worker_pool.raise_exceptions()
  File "/home/virtman/Durak_bot/venv/lib/python3.8/site-packages/telebot/util.py", line 130, in raise_exceptions
    raise self.exception_info
  File "/home/virtman/Durak_bot/venv/lib/python3.8/site-packages/telebot/util.py", line 82, in run
    task(*args, **kwargs)
  File "/home/virtman/Durak_bot/card-bot.py", line 69, in callback_inline
    game = active_game[call.from_user.id]
KeyError: 296957065
